<?xml version="1.0"?>
<robot xmlns:xacro="http://www.ros.org/wiki/xacro" >

    <xacro:include filename="inertial_macros.xacro"/>
    <xacro:include filename="gazebo_control.xacro" />

    <material name="white">
        <color rgba="1 1 1 1"/>
    </material>
    <material name="blue">
        <color rgba="0.2 0.2 1 1"/>
    </material>
    <material name="black">
        <color rgba="0 0 0 1"/>
    </material>
    <material name="red">
        <color rgba="1 0 0 1"/>
    </material>

    <!--BASE LINK-->
    <link name="base_link">
    </link>

    <!--BASE FOOTPRINT LINK-->
    <joint name="base_footprint_joint" type="fixed">
        <parent link="base_link"/>
        <child link="base_footprint"/>
        <origin xyz="0 0 0" rpy="0 0 0"/>
    </joint>

    <link name="base_footprint">
    </link>

    <!--CHASSI-->
    <joint name="chassi_joint" type="fixed">
        <parent link="base_link"/>
        <child link="chassi_link"/>
        <origin xyz="0 0 0"/> <!--VIRADO PARA X-->
        <!--<origin xyz="0 0 0" rpy="0 0 ${pi/2}"/> VIRADO PARA Y-->
    </joint>

    <link name="chassi_link">
        <visual>
            <origin xyz="0 0 0.085"/>
            <geometry>
                <cylinder radius="0.275" length="0.17"/>
            </geometry>
            <material name="white"/>
        </visual>
        <collision>
            <origin xyz="0 0 0.085"/>
            <geometry>
                <cylinder radius="0.275" length="0.17"/>
            </geometry>
        </collision>
        <xacro:inertial_cylinder mass="1.0" length="0.17" radius="0.275">
            <origin xyz="0 0 0.085" rpy="0 0 0"/>
        </xacro:inertial_cylinder>
    </link>

    <gazebo reference="chassi_link">
        <material>Gazebo/White</material>
    </gazebo>

    <!--LOWER BODY 35 +/- 14(junta)-->
    <joint name="lower_body_joint" type="prismatic">
        <parent link="base_link"/>
        <child link="lower_body_link"/>
        <origin xyz="0 0 0.17" rpy="0 0 0"/>
        <axis xyz="0 0 1"/>
        <limit lower="0" upper="0.14" velocity="100" effort="100"/>
    </joint>

    <link name="lower_body_link">
        <visual>
            <origin xyz="0 0 0.18" rpy="0 0 ${pi/2}"/>
            <geometry>
                <box size="0.2 0.05 0.35"/>
            </geometry>
            <material name="white"/>
        </visual>
        <collision>
            <origin xyz="0 0 0.18" rpy="0 0 ${pi/2}"/>
            <geometry>
                <box size="0.2 0.05 0.35"/>
            </geometry>
        </collision>
        <xacro:inertial_box mass="0.01" x="0.2" y="0.05" z="0.35">
            <origin xyz="0 0 0.18" rpy="0 0 0"/>
        </xacro:inertial_box>
    </link>

    <gazebo reference="lower_body_link">
        <material>Gazebo/White</material>
    </gazebo>

    <!--UPPER BODY 50-->
    <joint name="upper_body_joint" type="revolute">
        <parent link="lower_body_link"/>
        <child link="upper_body_link"/>
        <origin xyz="0 0 0.355" rpy="0 0 0"/>
        <axis xyz="0 1 0"/>
        <!--<limit lower="0.34" upper="1.38" velocity="100" effort="100"/>-->
        <limit lower="0" upper="1.38" velocity="100" effort="100"/>
    </joint>
        
    <link name="upper_body_link">
        <visual>
            <origin xyz="0 0 0.25" rpy="0 0 ${pi/2}"/>
            <geometry>
                <box size="0.2 0.05 0.50"/>
            </geometry>
            <material name="white"/>
        </visual>
        <collision>
            <origin xyz="0 0 0.25" rpy="0 0 ${pi/2}"/>
            <geometry>
                <box size="0.2 0.05 0.50"/>
            </geometry>
        </collision>
        <xacro:inertial_box mass="0.03" x="0.2" y="0.05" z="0.50">
            <origin xyz="0 0 0.25" rpy="0 0 0"/>
        </xacro:inertial_box>
    </link>

    <gazebo reference="upper_body_link">
        <material>Gazebo/White</material>
        <!--<turnGravityOff>true</turnGravityOff>
        <kp value="1000000.0"/>
        <kd value="1000000.0"/>
        <mu1 value="0.001"/>
        <mu2 value="0.001"/>--> 
    </gazebo>

    <joint name="aux_rear_box_joint" type="fixed">
        <parent link="upper_body_link"/>
        <child link="aux_rear_link"/>
        <origin xyz="-0.2 0 0.125" rpy="0 0 0"/>
    </joint>

     <link name="aux_rear_link">
        <collision>
            <origin xyz="0 0 0" rpy="0 0 0"/>
            <geometry>
                <box size="0.05 0.05 0.05"/>
            </geometry>
        </collision>
        <xacro:inertial_box mass="0.1" x="0.05" y="0.05" z="0.05">
            <origin xyz="0 0 0" rpy="0 0 0"/>
        </xacro:inertial_box>
    </link>


    <!--WHEELS-->

    <!--LEFT FRONT-->
    <joint name="left_front_joint" type="fixed">
        <parent link="chassi_link"/>
        <child link="left_front_link"/>
        <origin xyz="0.2 0.2 0" rpy="-${pi/2} 0 -${pi/4}"/>
    </joint>

    <link name="left_front_link">
        <visual>
            <geometry>
                <cylinder radius="0.1" length="0.04"/>
            </geometry>
            <material name="blue"/>
        </visual>
        <collision>
            <geometry>
                <cylinder radius="0.1" length="0.04"/>
            </geometry>
        </collision>
        <xacro:inertial_cylinder mass="0.1" length="0.04" radius="0.1">
            <origin xyz="0 0 0" rpy="0 0 0"/>
        </xacro:inertial_cylinder>
    </link>

    <gazebo reference="left_front_link">
        <material>Gazebo/Blue</material>
        <mu1 value="0.001"/>
        <mu2 value="0.001"/>
    </gazebo>

    <!--LEFT BACK-->
    <joint name="left_back_joint" type="fixed">
        <parent link="chassi_link"/>
        <child link="left_back_link"/>
        <origin xyz="-0.2 0.2 0" rpy="0 -${pi/2} -${pi/4}"/>
    </joint>

    <link name="left_back_link">
        <visual>
            <geometry>
                <cylinder radius="0.1" length="0.04"/>
            </geometry>
            <material name="black"/>
        </visual>
        <collision>
            <geometry>
                <cylinder radius="0.1" length="0.04"/>
            </geometry>
        </collision>
        <xacro:inertial_cylinder mass="0.1" length="0.04" radius="0.1">
            <origin xyz="0 0 0" rpy="0 0 0"/>
        </xacro:inertial_cylinder>
    </link>

    <gazebo reference="left_back_link">
        <material>Gazebo/Black</material>
        <mu1 value="0.001"/>
        <mu2 value="0.001"/>
    </gazebo>

    <!--RIGHT FRONT-->
    <joint name="right_front_joint" type="fixed">
        <parent link="chassi_link"/>
        <child link="right_front_link"/>
        <origin xyz="0.2 -0.2 0" rpy="0 ${pi/2} -${pi/4}"/>
    </joint>

    <link name="right_front_link">
        <visual>
            <geometry>
                <cylinder radius="0.1" length="0.04"/>
            </geometry>
            <material name="blue"/>
        </visual>
        <collision>
            <geometry>
                <cylinder radius="0.1" length="0.04"/>
            </geometry>
        </collision>
        <xacro:inertial_cylinder mass="0.1" length="0.04" radius="0.1">
            <origin xyz="0 0 0" rpy="0 0 0"/>
        </xacro:inertial_cylinder>
    </link>

    <gazebo reference="right_front_link">
        <material>Gazebo/Blue</material>
        <mu1 value="0.001"/>
        <mu2 value="0.001"/>
    </gazebo>

    <!--RIGHT BACK-->
    <joint name="right_back_joint" type="fixed">
        <parent link="chassi_link"/>
        <child link="right_back_link"/>
        <origin xyz="-0.2 -0.2 0" rpy="${pi/2} 0 -${pi/4}"/>
    </joint>

    <link name="right_back_link">
        <visual>
            <geometry>
                <cylinder radius="0.1" length="0.04"/>
            </geometry>
            <material name="black"/>
        </visual>
        <collision>
            <geometry>
                <cylinder radius="0.1" length="0.04"/>
            </geometry>
        </collision>
        <xacro:inertial_cylinder mass="0.1" length="0.04" radius="0.1">
            <origin xyz="0 0 0" rpy="0 0 0"/>
        </xacro:inertial_cylinder>
    </link>

    <gazebo reference="right_back_link">
        <material>Gazebo/Black</material>
        <mu1 value="0.001"/>
        <mu2 value="0.001"/>
    </gazebo>
    
    <xacro:omni_steering/>

</robot>